Workbook

Sheet Read me
A1: Akelius Quiz Cards · History curriculum map
A2: Proposal from Jonas von Essen, 2026-10-15. Draft for discussion with Daniel Shea.
A4: What this file is
A5: A model curriculum for the history cards from level 1 to university, as asked for in the email "Quiz Card curricula" of 15 October 2026: key topics per tier, a rough number of cards per topic, outcomes for every level, and a mapping to an academic standard.
A6: Levels are school years 1 to 12 plus U for university. A card is labelled by subject and level, for example H 3. Tiers group the levels: 1-3, 4-6, 7-9 and 10-U.
A7: 400 cards already exist: 80 topics with five cards each, at levels 6, 9, 12, 12 and U. The map places all of them and proposes 1,119 new cards.
A9: Sheets
A10: Summary: cards per tier, level, phase, region, strand and era. The numbers are formulas and update when the other sheets change.
A11: Tiers: what each tier covers and what a card looks like there.
A12: Topics: the curriculum map. One row per topic and tier, with levels, content, card numbers, outcomes and standard mapping.
A13: Cards by level: the cards of each topic row split over the levels.
A14: Level outcomes: what students can do by the end of each level, with the standard each outcome maps to.
... A31: About 1,500 cards in all: the 400 that exist and 1,119 new. Tier 1-3: 223 new cards. Tier 4-6: 320 cards, of which 80 exist. Tier 7-9: 405 cards, of which 80 exist. Tier 10-U: 571 cards, of which 240 exist. Most levels get about 90 to 125 cards, two or three a week over a school year. Level 1 has fewer, since each card holds one fact and is read aloud, and level 4 covers only the first humans to the first metals. The Cards by level sheet gives the number for every row and level. We suggest two phases. Phase 1 has 553 new cards, about 950 with the existing ones, and covers every outcome at least once, every topic already on our list and the topics closest to pupils in Tanzania and Bhutan. Phase 2 adds the remaining 566 cards for depth.

Sheet Summary
A1: Cards per tier
A2: Tier | B2: Topic rows | C2: Existing cards | D2: New cards | E2: Total cards | F2: Share of total
A3: Tier 1-3 | B3: =COUNTIF(Topics!$B$2:$B$213,A3) -> 31 | C3: =SUMIF(Topics!$B$2:$B$213,A3,Topics!$K$2:$K$213) -> 0 | D3: =SUMIF(Topics!$B$2:$B$213,A3,Topics!$L$2:$L$213) -> 223 | E3: =C3+D3 -> 223 | F3: =IF($E$7=0,0,E3/$E$7) -> 0.14680711
A4: Tier 4-6 | B4: =COUNTIF(Topics!$B$2:$B$213,A4) -> 46 | C4: =SUMIF(Topics!$B$2:$B$213,A4,Topics!$K$2:$K$213) -> 80 | D4: =SUMIF(Topics!$B$2:$B$213,A4,Topics!$L$2:$L$213) -> 240 | E4: =C4+D4 -> 320 | F4: =IF($E$7=0,0,E4/$E$7) -> 0.21066491
A5: Tier 7-9 | B5: =COUNTIF(Topics!$B$2:$B$213,A5) -> 72 | C5: =SUMIF(Topics!$B$2:$B$213,A5,Topics!$K$2:$K$213) -> 80 | D5: =SUMIF(Topics!$B$2:$B$213,A5,Topics!$L$2:$L$213) -> 325 | E5: =C5+D5 -> 405 | F5: =IF($E$7=0,0,E5/$E$7) -> 0.26662278
A6: Tier 10-U | B6: =COUNTIF(Topics!$B$2:$B$213,A6) -> 63 | C6: =SUMIF(Topics!$B$2:$B$213,A6,Topics!$K$2:$K$213) -> 240 | D6: =SUMIF(Topics!$B$2:$B$213,A6,Topics!$L$2:$L$213) -> 331 | E6: =C6+D6 -> 571 | F6: =IF($E$7=0,0,E6/$E$7) -> 0.3759052
A7: All tiers | B7: =SUM(B3:B6) -> 212 | C7: =SUM(C3:C6) -> 400 | D7: =SUM(D3:D6) -> 1119 | E7: =SUM(E3:E6) -> 1519 | F7: =IF($E$7=0,0,E7/$E$7) -> 1
A9: Cards per level
A10: Level | B10: Existing cards | C10: New cards | D10: Total cards
A11: Level 1 | B11: =COUNTIF('Existing cards'!$D$2:$D$401,"H 1") -> 0 | C11: =D11-B11 -> 51 | D11: =SUM('Cards by level'!D2:D213) -> 51
A12: Level 2 | B12: =COUNTIF('Existing cards'!$D$2:$D$401,"H 2") -> 0 | C12: =D12-B12 -> 68 | D12: =SUM('Cards by level'!E2:E213) -> 68
A13: Level 3 | B13: =COUNTIF('Existing cards'!$D$2:$D$401,"H 3") -> 0 | C13: =D13-B13 -> 104 | D13: =SUM('Cards by level'!F2:F213) -> 104
A14: Level 4 | B14: =COUNTIF('Existing cards'!$D$2:$D$401,"H 4") -> 0 | C14: =D14-B14 -> 62 | D14: =SUM('Cards by level'!G2:G213) -> 62
A15: Level 5 | B15: =COUNTIF('Existing cards'!$D$2:$D$401,"H 5") -> 0 | C15: =D15-B15 -> 87 | D15: =SUM('Cards by level'!H2:H213) -> 87
A16: Level 6 | B16: =COUNTIF('Existing cards'!$D$2:$D$401,"H 6") -> 80 | C16: =D16-B16 -> 91 | D16: =SUM('Cards by level'!I2:I213) -> 171
A17: Level 7 | B17: =COUNTIF('Existing cards'!$D$2:$D$401,"H 7") -> 0 | C17: =D17-B17 -> 120 | D17: =SUM('Cards by level'!J2:J213) -> 120
A18: Level 8 | B18: =COUNTIF('Existing cards'!$D$2:$D$401,"H 8") -> 0 | C18: =D18-B18 -> 100 | D18: =SUM('Cards by level'!K2:K213) -> 100
A19: Level 9 | B19: =COUNTIF('Existing cards'!$D$2:$D$401,"H 9") -> 80 | C19: =D19-B19 -> 105 | D19: =SUM('Cards by level'!L2:L213) -> 185
A20: Level 10 | B20: =COUNTIF('Existing cards'!$D$2:$D$401,"H 10") -> 0 | C20: =D20-B20 -> 89 | D20: =SUM('Cards by level'!M2:M213) -> 89
A21: Level 11 | B21: =COUNTIF('Existing cards'!$D$2:$D$401,"H 11") -> 0 | C21: =D21-B21 -> 125 | D21: =SUM('Cards by level'!N2:N213) -> 125
A22: Level 12 | B22: =COUNTIF('Existing cards'!$D$2:$D$401,"H 12") -> 160 | C22: =D22-B22 -> 78 | D22: =SUM('Cards by level'!O2:O213) -> 238
A23: Level U | B23: =COUNTIF('Existing cards'!$D$2:$D$401,"H U") -> 80 | C23: =D23-B23 -> 39 | D23: =SUM('Cards by level'!P2:P213) -> 119
A24: All levels | B24: =SUM(B11:B23) -> 400 | C24: =SUM(C11:C23) -> 1119 | D24: =SUM(D11:D23) -> 1519
A26: Cards per phase
A27: Value | B27: Topic rows | C27: Existing cards | D27: New cards | E27: Total cards | F27: Share of total
A28: Phase 1 | B28: =COUNTIF(Topics!$J$2:$J$213,A28) -> 83 | C28: =SUMIF(Topics!$J$2:$J$213,A28,Topics!$K$2:$K$213) -> 31 | D28: =SUMIF(Topics!$J$2:$J$213,A28,Topics!$L$2:$L$213) -> 553 | E28: =C28+D28 -> 584 | F28: =IF($E$7=0,0,E28/$E$7) -> 0.38446346
A29: Phase 2 | B29: =COUNTIF(Topics!$J$2:$J$213,A29) -> 110 | C29: =SUMIF(Topics!$J$2:$J$213,A29,Topics!$K$2:$K$213) -> 241 | D29: =SUMIF(Topics!$J$2:$J$213,A29,Topics!$L$2:$L$213) -> 566 | E29: =C29+D29 -> 807 | F29: =IF($E$7=0,0,E29/$E$7) -> 0.53127057
A30: Existing only | B30: =COUNTIF(Topics!$J$2:$J$213,A30) -> 19 | C30: =SUMIF(Topics!$J$2:$J$213,A30,Topics!$K$2:$K$213) -> 128 | D30: =SUMIF(Topics!$J$2:$J$213,A30,Topics!$L$2:$L$213) -> 0 | E30: =C30+D30 -> 128 | F30: =IF($E$7=0,0,E30/$E$7) -> 0.084265964
A32: Cards per region
A33: Value | B33: Topic rows | C33: Existing cards | D33: New cards | E33: Total cards | F33: Share of total
A34: Africa | B34: =COUNTIF(Topics!$G$2:$G$213,A34) -> 35 | C34: =SUMIF(Topics!$G$2:$G$213,A34,Topics!$K$2:$K$213) -> 24 | D34: =SUMIF(Topics!$G$2:$G$213,A34,Topics!$L$2:$L$213) -> 226 | E34: =C34+D34 -> 250 | F34: =IF($E$7=0,0,E34/$E$7) -> 0.16458196
A35: Asia and Pacific | B35: =COUNTIF(Topics!$G$2:$G$213,A35) -> 41 | C35: =SUMIF(Topics!$G$2:$G$213,A35,Topics!$K$2:$K$213) -> 33 | D35: =SUMIF(Topics!$G$2:$G$213,A35,Topics!$L$2:$L$213) -> 209 | E35: =C35+D35 -> 242 | F35: =IF($E$7=0,0,E35/$E$7) -> 0.15931534
A36: Europe | B36: =COUNTIF(Topics!$G$2:$G$213,A36) -> 35 | C36: =SUMIF(Topics!$G$2:$G$213,A36,Topics!$K$2:$K$213) -> 115 | D36: =SUMIF(Topics!$G$2:$G$213,A36,Topics!$L$2:$L$213) -> 132 | E36: =C36+D36 -> 247 | F36: =IF($E$7=0,0,E36/$E$7) -> 0.16260698
A37: Global | B37: =COUNTIF(Topics!$G$2:$G$213,A37) -> 69 | C37: =SUMIF(Topics!$G$2:$G$213,A37,Topics!$K$2:$K$213) -> 174 | D37: =SUMIF(Topics!$G$2:$G$213,A37,Topics!$L$2:$L$213) -> 402 | E37: =C37+D37 -> 576 | F37: =IF($E$7=0,0,E37/$E$7) -> 0.37919684
A38: Latin America | B38: =COUNTIF(Topics!$G$2:$G$213,A38) -> 13 | C38: =SUMIF(Topics!$G$2:$G$213,A38,Topics!$K$2:$K$213) -> 15 | D38: =SUMIF(Topics!$G$2:$G$213,A38,Topics!$L$2:$L$213) -> 63 | E38: =C38+D38 -> 78 | F38: =IF($E$7=0,0,E38/$E$7) -> 0.051349572
A39: Middle East | B39: =COUNTIF(Topics!$G$2:$G$213,A39) -> 13 | C39: =SUMIF(Topics!$G$2:$G$213,A39,Topics!$K$2:$K$213) -> 34 | D39: =SUMIF(Topics!$G$2:$G$213,A39,Topics!$L$2:$L$213) -> 64 | E39: =C39+D39 -> 98 | F39: =IF($E$7=0,0,E39/$E$7) -> 0.064516129
A40: North America | B40: =COUNTIF(Topics!$G$2:$G$213,A40) -> 6 | C40: =SUMIF(Topics!$G$2:$G$213,A40,Topics!$K$2:$K$213) -> 5 | D40: =SUMIF(Topics!$G$2:$G$213,A40,Topics!$L$2:$L$213) -> 23 | E40: =C40+D40 -> 28 | F40: =IF($E$7=0,0,E40/$E$7) -> 0.01843318
A42: Cards per strand
A43: Value | B43: Topic rows | C43: Existing cards | D43: New cards | E43: Total cards | F43: Share of total
A44: belief and ideas | B44: =COUNTIF(Topics!$H$2:$H$213,A44) -> 26 | C44: =SUMIF(Topics!$H$2:$H$213,A44,Topics!$K$2:$K$213) -> 97 | D44: =SUMIF(Topics!$H$2:$H$213,A44,Topics!$L$2:$L$213) -> 121 | E44: =C44+D44 -> 218 | F44: =IF($E$7=0,0,E44/$E$7) -> 0.14351547
...

Sheet Topics
A1: Topic ID | B1: Tier | C1: Levels | D1: Topic | E1: Key content | F1: Era | G1: Region | H1: Strand | I1: Status | J1: Phase | K1: Existing cards | L1: New cards | M1: Total cards | N1: Outcomes | O1: Standard mapping | P1: Existing card set | Q1: Notes
A2: T1-3-001 | B2: Tier 1-3 | C2: 1 | D2: Time words, days and calendars | E2: Before and after, moon months, the farming year, counting days by sun, moon and rain. | F2: Across time | G2: Global | H2: time and evidence | I2: new | J2: Phase 1 | K2: 0 | L2: 10 | M2: =K2+L2 -> 10 | N2: H1.1 | O2: NCHS K-4 Historical Thinking Standard 1, Chronological Thinking; BNCC EF02HI06; Cambridge Primary Humanities 0065, Past strand | Q2: By level: 1: 10 new. Phase 1.
A3: T1-3-002 | B3: Tier 1-3 | C3: 1, 2 | D3: Children, families and school then and now | E3: Chores, games and toys, a grandparent's childhood, learning from elders, scribe and monastery schools. | F3: Across time | G3: Global | H3: people and everyday life | I3: new | J3: Phase 2 | K3: 0 | L3: 12 | M3: =K3+L3 -> 12 | N3: H1.3, H2.7 | O3: NCHS K-4 Topic 1, Standard 1; Tanzania HTM primary 2023, Std III | Q3: By level: 1: 7 new; 2: 5 new. Childhood is a gap in the existing sets. Many pupils still learn at home and in monastery schools, so cards show what changed and what stayed. Phase 2.
A4: T1-3-003 | B4: Tier 1-3 | C4: 1, 2 | D4: Homes, tools and food through time | E4: Round huts and stilt houses, cooking fire to stove, oil lamp to bulb, clay pot to metal pot. | F4: Across time | G4: Global | H4: people and everyday life | I4: new | J4: Phase 2 | K4: 0 | L4: 10 | M4: =K4+L4 -> 10 | N4: H1.2, H1.3, H2.7 | O4: NCHS K-4 Topic 4, Standard 8A; NCHS K-4 Topic 1, Standard 1 | Q4: By level: 1: 6 new; 2: 4 new. The Himalayan farmhouse and grinding grain belong to T1-3-030. Phase 2.
A5: T1-3-004 | B5: Tier 1-3 | C5: 1, 2 | D5: Clues from the past | E5: Objects, photos, buildings, bones and stories; what museums and archaeologists do. | F5: Across time | G5: Global | H5: time and evidence | I5: new | J5: Phase 1 | K5: 0 | L5: 10 | M5: =K5+L5 -> 10 | N5: H1.4, H2.6 | O5: Cambridge Primary Humanities 0065, Past strand, how we construct the past; NCHS K-4 Topic 4, Standard 7A | Q5: By level: 1: 6 new; 2: 4 new. Phase 1.
A6: T1-3-005 | B6: Tier 1-3 | C6: 1, 2 | D6: Stories, songs and festivals | E6: Harvest and new year festivals, masked dances in Bhutan, Anansi and the clever hare. | F6: Across time | G6: Global | H6: belief and ideas | I6: new | J6: Phase 2 | K6: 0 | L6: 10 | M6: =K6+L6 -> 10 | N6: H1.5, H2.8 | O6: NCHS K-4 Topic 4, Standard 7A, folktales, holidays and ceremonies; Tanzania HTM primary 2023, Std III | Q6: By level: 1: 6 new; 2: 4 new. Faith festivals are shown as what believers do. Phase 2.
A7: T1-3-006 | B7: Tier 1-3 | C7: 1, 2, 3 | D7: Travel and messages, from feet to rockets | E7: Camels, canoes, trains and planes; runners, talking drums, letters and satellites. | F7: Across time | G7: Global | H7: trade, travel and exchange | I7: new | J7: Phase 1 | K7: 0 | L7: 10 | M7: =K7+L7 -> 10 | N7: H1.6, H2.8, H3.4 | O7: NCHS K-4 Topic 4, Standards 8B and 8C | Q7: By level: 1: 5 new; 2: 3 new; 3: 2 new. Phase 1.
A8: T1-3-007 | B8: Tier 1-3 | C8: 1 | D8: Leaders and rules: elders, chiefs and councils | E8: Who makes rules at home, at school and in a village; clan elders and chiefs in East Africa long ago; choosing leaders today. | F8: Across time | G8: Africa | H8: power and government | I8: new | J8: Phase 1 | K8: 0 | L8: 6 | M8: =K8+L8 -> 6 | N8: H1.7 | O8: WHFUA key theme Uses and Abuses of Power; Tanzania HTM primary 2023, Std III; Bhutan Social Studies 2025, Class IV | Q8: By level: 1: 6 new. Neutral tone, not the HTM values framing. Named systems such as Maasai age sets and Buganda belong to T4-6-038. Phase 1.
A9: T1-3-008 | B9: Tier 1-3 | C9: 2 | D9: Our oldest ancestors, in East Africa | E9: Laetoli footprints and Lucy as human ancestors, not people like us; Olduvai tools; how we know people began in Africa. | F9: Big Era 1, before 200,000 years ago | G9: Africa | H9: people and everyday life | I9: new | J9: Phase 1 | K9: 0 | L9: 8 | M9: =K9+L9 -> 8 | N9: H2.1, H2.6 | O9: WHFUA Big Era 1, Landscape 1.2; NCHS World History Era 1, Standard 1 | Q9: By level: 2: 8 new. The most local topic for Tanzania. Cards say 'the oldest found so far'. Laetoli, Olduvai and Lucy belong to this row. Phase 1.
A10: T1-3-009 | B10: Tier 1-3 | C10: 2 | D10: Stone tools, fire and shelter | E10: Hand axes, blades, cooking with fire, clothes and shelters. | F10: Big Era 2, 200,000 to 10,000 years ago | G10: Global | H10: science, technology and mathematics | I10: new | J10: Phase 1 | K10: 0 | L10: 7 | M10: =K10+L10 -> 7 | N10: H2.3 | O10: NCHS K-4 Topic 4, Standard 8A | Q10: By level: 2: 7 new. Say people used fire for a very long time; no exact first dates at this level. Phase 1.
A11: T1-3-010 | B11: Tier 1-3 | C11: 2 | D11: Hunting, fishing and gathering | E11: Finding fruit, roots, fish and meat, moving with the seasons. | F11: Big Era 2, 200,000 to 10,000 years ago | G11: Global | H11: people and everyday life | I11: new | J11: Phase 1 | K11: 0 | L11: 6 | M11: =K11+L11 -> 6 | N11: H2.2 | O11: NCHS K-4 Topic 4, Standard 8A; WHFUA Big Era 2, Landscape 2.1 | Q11: By level: 2: 6 new. Living hunter-gatherers, such as the Hadza of Tanzania, are shown with respect and in the present. Phase 1.
A12: T1-3-011 | B12: Tier 1-3 | C12: 2 | D12: Rock art and beads | E12: Hand stencils on Sulawesi, ostrich-egg beads, Australian rock art. | F12: Big Era 2, 200,000 to 10,000 years ago | G12: Global | H12: belief and ideas | I12: new | J12: Phase 1 | K12: 0 | L12: 6 | M12: =K12+L12 -> 6 | N12: H2.4 | O12: WHFUA Big Era 2, Landscape 2.1; NCHS K-4 Topic 4, Standard 7A | Q12: By level: 2: 6 new. Blombos and Lascaux belong to T4-6-005 and the Kondoa paintings to T1-3-029. Phase 1.
A13: T1-3-012 | B13: Tier 1-3 | C13: 2 | D13: People reach every continent | E13: Walking out of Africa, the first boats across the sea, crossing the land bridge to the Americas. | F13: Big Era 2, 200,000 to 10,000 years ago | G13: Global | H13: trade, travel and exchange | I13: new | J13: Phase 1 | K13: 0 | L13: 6 | M13: =K13+L13 -> 6 | N13: H2.5 | O13: NCHS K-4 Topic 4, Standard 7B; WHFUA Big Era 2, Landscape 2.1 | Q13: By level: 2: 6 new. Phase 1.
... A40: T4-6-008 | B40: Tier 4-6 | C40: 4 | D40: Metals, wheels and horses | E40: Copper and bronze, wheels, the tamed horse, chariots, iron. | F40: Big Era 3, 8000-1000 BCE | G40: Global | H40: science, technology and mathematics | I40: new | J40: Phase 1 | K40: 0 | L40: 8 | M40: =K40+L40 -> 8 | N40: H4.7 | O40: NCHS World History Era 2, Standard 3; WHFUA Big Era 3, Landscape 3.4 | Q40: By level: 4: 8 new. Phase 1.
A41: T4-6-009 | B41: Tier 4-6 | C41: 5, 6 | D41: Ancient Egypt | E41: Hatshepsut and the voyage to Punt, the Deir el-Medina tomb builders and the first recorded strike, Akhenaten's one-god belief marked as belief, medicine on papyrus. | F41: Big Era 3, 8000-1000 BCE | G41: Africa | H41: people and everyday life | I41: existing + new | J41: Phase 2 | K41: 1 | L41: 6 | M41: =K41+L41 -> 7 | N41: H5.1, H5.3, H5.6, H6.7 | O41: NCHS World History Era 2, Standard 1; WHFUA Big Era 3, Landscape 3.3; Kenya KICD Junior School Grade 7 | P41: ancient-egypt-pyramids | Q41: By level: 5: 4 new; 6: 2 new, 1 existing. Counted as Africa. The Nile farmers, scribes, hieroglyphs, the afterlife and the Rosetta Stone are on the existing cards. Phase 2.
A42: T4-6-010 | B42: Tier 4-6 | C42: 5, 6 | D42: Mesopotamia and the first law codes | E42: Sargon of Akkad, Enheduanna the first named author, counting in sixties, the library of Nineveh. | F42: Big Era 3, 8000-1000 BCE | G42: Middle East | H42: power and government | I42: existing + new | J42: Phase 2 | K42: 2 | L42: 5 | M42: =K42+L42 -> 7 | N42: H5.1, H5.2, H5.5, H6.7 | O42: NCHS World History Era 2, Standard 1; WHFUA Big Era 3, Landscape 3.3; England National Curriculum 2013, KS2, Sumer | P42: mesopotamia, hammurabi | Q42: By level: 5: 5 new; 6: 2 existing. Ziggurats, cuneiform, Babylon and the law stone are on the existing cards. Phase 2.
A43: T4-6-011 | B43: Tier 4-6 | C43: 5 | D43: The Indus valley civilisation | E43: Harappa, Mohenjo-daro, drains, weights, seals, an unread script, why the cities declined. | F43: Big Era 3, 8000-1000 BCE | G43: Asia and Pacific | H43: people and everyday life | I43: new | J43: Phase 2 | K43: 0 | L43: 8 | M43: =K43+L43 -> 8 | N43: H5.1, H5.5, H5.7 | O43: NCHS World History Era 2, Standard 1; WHFUA Big Era 3, Landscape 3.3; NCERT Exploring Society Grade 6 | Q43: By level: 5: 8 new. A gap in the existing sets. Cities declined as rivers and rain changed; there was no Aryan invasion. Seals are shown without readable signs. Phase 2.
A44: T4-6-012 | B44: Tier 4-6 | C44: 5 | D44: Early China: Shang and Zhou | E44: Oracle bones, bronze casting, the Mandate of Heaven. | F44: Big Era 3, 8000-1000 BCE | G44: Asia and Pacific | H44: power and government | I44: new | J44: Phase 2 | K44: 0 | L44: 6 | M44: =K44+L44 -> 6 | N44: H5.1, H5.2 | O44: NCHS World History Era 2, Standard 2; WHFUA Big Era 3, Landscape 3.3; England National Curriculum 2013, KS2, Shang | Q44: By level: 5: 6 new. A gap in the existing sets. Oracle bones are shown without readable characters. Phase 2.
A45: T4-6-013 | B45: Tier 4-6 | C45: 5 | D45: How writing began around the world | E45: Writing invented separately in Mesoamerica; Linear B read by Michael Ventris. | F45: Big Eras 3-4, 8000 BCE to 500 CE | G45: Global | H45: science, technology and mathematics | I45: new | J45: Phase 1 | K45: 0 | L45: 2 | M45: =K45+L45 -> 2 | N45: H5.2, H5.7 | O45: NCHS World History Era 2, 1A; WHFUA Big Era 4, Landscape 4.6 | Q45: By level: 5: 2 new. Writing in Mesopotamia and old scripts read again are on existing cards. Avoid the Rosetta Stone motif. No readable signs in images. Phase 1.
A46: T4-6-014 | B46: Tier 4-6 | C46: 5, 6 | D46: Kush and Nubia | E46: Kerma, the pharaohs from the south, iron and pyramids of Meroe. | F46: Big Eras 3-4, 8000 BCE to 500 CE | G46: Africa | H46: power and government | I46: planned | J46: Phase 1 | K46: 0 | L46: 7 | M46: =K46+L46 -> 7 | N46: H5.4, H6.1 | O46: NCHS World History Era 3, 1C; WHFUA Big Era 4, Landscape 4.3; Kenya KICD Junior School Grade 8 | Q46: By level: 5: 5 new; 6: 2 new. Raised from 3 to 7 cards because Egypt is the only ancient African state in the existing sets. Planned topic #89 on the Akelius topic list. Phase 1.
A47: T4-6-015 | B47: Tier 4-6 | C47: 5 | D47: Bronze Age Crete, Mycenae and the collapse | E47: Minoan palaces, the tin trade, the fall of states around 1200 BCE. | F47: Big Era 3, 8000-1000 BCE | G47: Europe | H47: trade, travel and exchange | I47: new | J47: Phase 2 | K47: 0 | L47: 4 | M47: =K47+L47 -> 4 | N47: H5.4 | O47: NCHS World History Era 2, 2B and Standard 3 | Q47: By level: 5: 4 new. Phase 2.
A48: T4-6-016 | B48: Tier 4-6 | C48: 5 | D48: First civilisations of the Americas | E48: Caral, the Olmec, Chavin, Teotihuacan, Moche, Nazca. | F48: Big Eras 3-4, 8000 BCE to 500 CE | G48: Latin America | H48: people and everyday life | I48: new | J48: Phase 1 | K48: 0 | L48: 8 | M48: =K48+L48 -> 8 | N48: H5.4 | O48: NCHS World History Era 3, Standard 4; WHFUA Big Era 3, Landscape 3.5, and Big Era 4, Landscape 4.6 | Q48: By level: 5: 8 new. A gap in the existing sets, which start the Americas with the Maya. Phase 1.
A49: T4-6-017 | B49: Tier 4-6 | C49: 5, 6 | D49: The Phoenicians, Carthage and the voyage of Hanno | E49: Hanno's voyage along West Africa, Carthage's harbour and farms, Hannibal. | F49: Big Eras 3-4, 8000 BCE to 500 CE | G49: Africa | H49: trade, travel and exchange | I49: existing + new | J49: Phase 2 | K49: 1 | L49: 3 | M49: =K49+L49 -> 4 | N49: H5.4, H6.7 | O49: WHFUA Big Era 4, Landscape 4.1 | P49: phoenicians-alphabet | Q49: By level: 5: 2 new; 6: 1 new, 1 existing. Carthage lay in today's Tunisia; the existing Phoenician card is counted as Middle East. Carthage is named on phoenicians card 3, so answers are Hanno, Hannibal or the harbour, not Carthage. Phase 2.
A50: T4-6-018 | B50: Tier 4-6 | C50: 5, 6 | D50: Ancient Israel and Judaism | E50: The Hebrew Bible, belief in one God, exile in Babylon, Torah and synagogue. | F50: Big Era 4, 1200 BCE to 500 CE | G50: Middle East | H50: belief and ideas | I50: new | J50: Phase 1 | K50: 0 | L50: 6 | M50: =K50+L50 -> 6 | N50: H5.6, H6.3 | O50: NCHS World History Era 3, Standard 1; Tanzania History A-level 2023, Form V | Q50: By level: 5: 4 new; 6: 2 new. A gap: in the existing cards Jews appear mostly as victims. Abraham, Moses and the Exodus are told as tradition and belief; archaeology confirms the kingdoms of Israel and Judah and the exile. Phase 1.
A51: T4-6-019 | B51: Tier 4-6 | C51: 5, 6 | D51: Hinduism, Jainism and the Vedic tradition | E51: The Vedas, dharma and karma, the epics, Mahavira, caste as history. | F51: Big Era 4, 1200 BCE to 500 CE | G51: Asia and Pacific | H51: belief and ideas | I51: new | J51: Phase 2 | K51: 0 | L51: 6 | M51: =K51+L51 -> 6 | N51: H5.6, H6.3 | O51: NCHS World History Era 3, Standard 3; NCERT Exploring Society Grade 6, cultural roots | Q51: By level: 5: 4 new; 6: 2 new. A gap in the existing sets. Belief marked as belief. Phase 2.
A52: T4-6-020 | B52: Tier 4-6 | C52: 5, 6 | D52: Work, families and slavery in the ancient world | E52: Farmers, crafts, women and children, slavery, serfdom and free work compared. | F52: Big Eras 3-4, 8000 BCE to 500 CE | G52: Global | H52: people and everyday life | I52: new | J52: Phase 2 | K52: 0 | L52: 7 | M52: =K52+L52 -> 7 | N52: H5.3, H6.2 | O52: WHFUA key theme Haves and Have-Nots; BNCC EF06HI17 | Q52: By level: 5: 4 new; 6: 3 new. The history of the 99 percent. Phase 2.
A53: T4-6-021 | B53: Tier 4-6 | C53: 5, 6 | D53: Persia: the Achaemenid empire | E53: Cyrus, Darius, the Royal Road, the Cyrus Cylinder, Persepolis, Ahuramazda in royal inscriptions. | F53: Big Era 4, 1200 BCE to 500 CE | G53: Middle East | H53: power and government | I53: new | J53: Phase 2 | K53: 0 | L53: 6 | M53: =K53+L53 -> 6 | N53: H5.5, H6.1 | O53: WHFUA Big Era 4, Landscape 4.4 | Q53: By level: 5: 2 new; 6: 4 new. A gap: Persia now appears only as Alexander's enemy. Persia is named on several existing cards, so answers are people, places or things such as Darius or the Royal Road. The Cyrus Cylinder praises Cyrus and tells how he returned gods and peoples to their homes; never call it the first human rights charter. Whether the kings were Zoroastrian is debated, so mark it as belief and as uncertain. Phase 2.
A54: T4-6-022 | B54: Tier 4-6 | C54: 6 | D54: Ancient Greece and the Olympic Games | E54: Sparta, the Persian wars, Herodotus, Hippocrates. | F54: Big Era 4, 1200 BCE to 500 CE | G54: Europe | H54: power and government | I54: existing + new | J54: Phase 2 | K54: 2 | L54: 4 | M54: =K54+L54 -> 6 | N54: H6.2, H6.7 | O54: NCHS World History Era 3, 2A; England National Curriculum 2013, KS2, Ancient Greece | P54: ancient-greece, olympic-games | Q54: By level: 6: 4 new, 2 existing. City-states, democracy and theatre are on the existing cards. No Olympic rings. Phase 2.
A55: T4-6-023 | B55: Tier 4-6 | C55: 6 | D55: Socrates, Plato and Aristotle | E55: One simple card each on Socrates, Plato and Aristotle. | F55: Big Era 4, 1200 BCE to 500 CE | G55: Europe | H55: belief and ideas | I55: existing | J55: Existing only | K55: 3 | L55: 0 | M55: =K55+L55 -> 3 | N55: H6.7 | O55: NCHS World History Era 3, Standard 2 | P55: socrates, plato, aristotle | Q55: By level: 6: 3 existing.
A56: T4-6-024 | B56: Tier 4-6 | C56: 6 | D56: Alexander the Great | E56: One simple card on Alexander the Great. | F56: Big Era 4, 1200 BCE to 500 CE | G56: Europe | H56: power and government | I56: existing | J56: Existing only | K56: 1 | L56: 0 | M56: =K56+L56 -> 1 | N56: H6.1, H6.7 | O56: NCHS World History Era 3, Standard 2 | P56: alexander-the-great | Q56: By level: 6: 1 existing.
A57: T4-6-025 | B57: Tier 4-6 | C57: 6 | D57: Archimedes and the scholars of Alexandria | E57: Euclid and the idea of proof, Eratosthenes measures the Earth, Hypatia, Hero's steam toy. | F57: Big Era 4, 1200 BCE to 500 CE | G57: Europe | H57: science, technology and mathematics | I57: existing + new | J57: Phase 1 | K57: 1 | L57: 6 | M57: =K57+L57 -> 7 | N57: H6.6, H6.7 | O57: NCHS World History Era 3, Standard 2; WHFUA Big Era 4, Landscape 4.4 | P57: archimedes | Q57: By level: 6: 6 new, 1 existing. The library of Alexandria is on an existing card. If a card mentions it: the library shrank over centuries, with no single great fire. Hypatia was killed in 415 in a political feud; her death did not end ancient science. Planned topics #60, #70 on the Akelius topic list. Phase 1.
A58: T4-6-026 | B58: Tier 4-6 | C58: 5, 6 | D58: Confucius, Laozi and the Hundred Schools | E58: Laozi and Daoism, Mencius, Mozi, the Legalists. | F58: Big Era 4, 1200 BCE to 500 CE | G58: Asia and Pacific | H58: belief and ideas | I58: existing + new | J58: Phase 2 | K58: 1 | L58: 4 | M58: =K58+L58 -> 5 | N58: H5.6, H6.7 | O58: WHFUA Big Era 4, Landscape 4.2 | P58: confucius | Q58: By level: 5: 3 new; 6: 1 new, 1 existing. Confucian rule is on the existing cards. Phase 2.
A59: T4-6-027 | B59: Tier 4-6 | C59: 5, 6 | D59: The Buddha and Buddhism in the Himalaya | E59: Guru Rinpoche and Taktsang, Songtsen Gampo and the first temples of Tibet and Bhutan, Mahayana and Theravada. | F59: Big Eras 4-5, 1200 BCE to 1500 CE | G59: Asia and Pacific | H59: belief and ideas | I59: existing + new | J59: Phase 1 | K59: 1 | L59: 6 | M59: =K59+L59 -> 7 | N59: H5.6, H6.3, H6.7 | O59: NCHS World History Era 4, 1B; Bhutan Social Studies 2025, Class IV; Bhutan History Framework 2022, Class VIII | P59: siddhartha-gautama | Q59: By level: 5: 2 new; 6: 4 new, 1 existing. The first cards that name Bhutan. Bhutanese tradition says Guru Rinpoche came in the 700s; the story of his flight to Taktsang is marked as tradition, and so is the founding of the first temples. Phase 1.
A60: T4-6-028 | B60: Tier 4-6 | C60: 5, 6 | D60: Rome: republic and empire | E60: Pompeii, Spartacus, Leptis Magna in Roman Africa, Roman women and families. | F60: Big Era 4, 1200 BCE to 500 CE | G60: Europe | H60: power and government | I60: existing + new | J60: Phase 2 | K60: 3 | L60: 4 | M60: =K60+L60 -> 7 | N60: H5.3, H6.1, H6.2, H6.7 | O60: NCHS World History Era 3, 3A; NCERT Themes in World History Class 11, An Empire Across Three Continents | P60: roman-republic-empire, julius-caesar, augustus | Q60: By level: 5: 2 new; 6: 2 new, 3 existing. Roads, aqueducts and citizens are on the existing cards. Phase 2.
A61: T4-6-029 | B61: Tier 4-6 | C61: 6 | D61: Jesus and the spread of Christianity | E61: Early communities, Paul's journeys, Constantine's freedom of worship in 313, Theodosius makes it the state religion in 380, Armenia's early church. | F61: Big Era 4, 1200 BCE to 500 CE | G61: Middle East | H61: belief and ideas | I61: existing + new | J61: Phase 2 | K61: 1 | L61: 4 | M61: =K61+L61 -> 5 | N61: H6.3, H6.7 | O61: NCHS World History Era 3, Standard 3, and Era 4, 1B | P61: jesus-of-nazareth | Q61: By level: 6: 4 new, 1 existing. Jesus only from afar or from behind. Belief marked as belief. Aksum belongs to T4-6-033. Phase 2.
A62: T4-6-030 | B62: Tier 4-6 | C62: 5, 6 | D62: Ashoka, the Maurya and the Gupta age | E62: Decimal place value in the Gupta age, Aryabhata in 499, Nalanda, the iron pillar of Delhi, and after the Gupta age Brahmagupta's rules for zero in 628. | F62: Big Era 4, 1200 BCE to 500 CE | G62: Asia and Pacific | H62: science, technology and mathematics | I62: existing + new | J62: Phase 1 | K62: 1 | L62: 6 | M62: =K62+L62 -> 7 | N62: H5.5, H6.1, H6.6, H6.7 | O62: NCHS World History Era 4, 1C; NCERT Exploring Society Grade 7, the Gupta era | P62: ashoka | Q62: By level: 5: 2 new; 6: 4 new, 1 existing. Ashoka's edicts are on the existing cards. Brahmagupta worked after the Gupta empire fell. Planned topic #63 on the Akelius topic list. Phase 1.
A63: T4-6-031 | B63: Tier 4-6 | C63: 5, 6 | D63: The first emperor and Han China | E63: Liu Bang and Han rule, officials chosen by recommendation and trained at the Imperial Academy, Zhang Heng's earthquake detector, the historian Ban Zhao. | F63: Big Era 4, 1200 BCE to 500 CE | G63: Asia and Pacific | H63: power and government | I63: existing + new | J63: Phase 2 | K63: 1 | L63: 5 | M63: =K63+L63 -> 6 | N63: H5.3, H6.1, H6.6, H6.7 | O63: WHFUA Big Era 4, Landscapes 4.2 and 4.5 | P63: qin-shi-huangdi | Q63: By level: 5: 2 new; 6: 3 new, 1 existing. Han China is a gap in the existing sets. Written exams for officials start under the Sui and Tang and belong to T7-9-007. Paper was in use in the 100s BCE and improved by Cai Lun in 105 CE; the paper card itself is in T1-3-016. Sima Qian is named on qin card 5, so he is never an answer. Phase 2.
A64: T4-6-032 | B64: Tier 4-6 | C64: 6 | D64: The Silk Road | E64: Sogdian merchants and their letters, paper known in Central Asia before Islam. | F64: Big Eras 4-5, 1200 BCE to 1500 CE | G64: Asia and Pacific | H64: trade, travel and exchange | I64: existing + new | J64: Phase 2 | K64: 1 | L64: 2 | M64: =K64+L64 -> 3 | N64: H6.4, H6.7 | O64: WHFUA Big Era 4, Landscape 4.5 | P64: silk-road | Q64: By level: 6: 2 new, 1 existing. Envoys, silk, horses, Buddhism, Samarkand and Chang'an are on the existing cards. The story that prisoners from the battle of Talas in 751 brought papermaking west is a later legend; silk-road card 3 tells it as 'a story says', and a new card tests it only as a myth. Phase 2.
A65: T4-6-033 | B65: Tier 4-6 | C65: 5, 6 | D65: Aksum | E65: Obelisks, coins, a Christian kingdom, Red Sea trade with India. | F65: Big Era 4, 1200 BCE to 500 CE | G65: Africa | H65: trade, travel and exchange | I65: planned | J65: Phase 1 | K65: 0 | L65: 6 | M65: =K65+L65 -> 6 | N65: H5.5, H6.1, H6.3 | O65: NCHS World History Era 3, 1C; WHFUA Big Era 4, Landscape 4.3; Kenya KICD Senior School Grade 10 | Q65: By level: 5: 2 new; 6: 4 new. Aksum belongs to this row. The Queen of Sheba and the Ark of the Covenant are told as legend from the Kebra Nagast. Planned topic #90 on the Akelius topic list. Phase 1.
A66: T4-6-034 | B66: Tier 4-6 | C66: 5, 6 | D66: The Bantu expansion, iron and the Nok | E66: Bantu-speaking farmers spread from near today's Cameroon and mixed with other peoples; iron working; the Nok of Nigeria, a different people; Swahili's language family; Nilotes and Cushites. | F66: Big Era 4, 1200 BCE to 500 CE | G66: Africa | H66: people and everyday life | I66: new | J66: Phase 1 | K66: 0 | L66: 10 | M66: =K66+L66 -> 10 | N66: H5.4, H6.5 | O66: NCHS World History Era 4, 5A; WHFUA Big Era 4, Landscape 4.3; Tanzania HTM Form I 2023 | Q66: By level: 5: 3 new; 6: 7 new. Local for Tanzania. Tanzanian syllabi say migration; cards explain both words, migration and gradual spread. Phase 1.
...

Sheet Cards by level
A1: Topic ID | B1: Tier | C1: Topic | D1: L1 | E1: L2 | F1: L3 | G1: L4 | H1: L5 | I1: L6 | J1: L7 | K1: L8 | L1: L9 | M1: L10 | N1: L11 | O1: L12 | P1: U | Q1: Total | R1: Check
A2: T1-3-001 | B2: Tier 1-3 | C2: Time words, days and calendars | D2: 10 | Q2: =SUM(D2:P2) -> 10 | R2: =IF(Q2=Topics!M2,"ok","differs from Topics") -> ok
A3: T1-3-002 | B3: Tier 1-3 | C3: Children, families and school then and now | D3: 7 | E3: 5 | Q3: =SUM(D3:P3) -> 12 | R3: =IF(Q3=Topics!M3,"ok","differs from Topics") -> ok
A4: T1-3-003 | B4: Tier 1-3 | C4: Homes, tools and food through time | D4: 6 | E4: 4 | Q4: =SUM(D4:P4) -> 10 | R4: =IF(Q4=Topics!M4,"ok","differs from Topics") -> ok
A5: T1-3-004 | B5: Tier 1-3 | C5: Clues from the past | D5: 6 | E5: 4 | Q5: =SUM(D5:P5) -> 10 | R5: =IF(Q5=Topics!M5,"ok","differs from Topics") -> ok
A6: T1-3-005 | B6: Tier 1-3 | C6: Stories, songs and festivals | D6: 6 | E6: 4 | Q6: =SUM(D6:P6) -> 10 | R6: =IF(Q6=Topics!M6,"ok","differs from Topics") -> ok
A7: T1-3-006 | B7: Tier 1-3 | C7: Travel and messages, from feet to rockets | D7: 5 | E7: 3 | F7: 2 | Q7: =SUM(D7:P7) -> 10 | R7: =IF(Q7=Topics!M7,"ok","differs from Topics") -> ok
A8: T1-3-007 | B8: Tier 1-3 | C8: Leaders and rules: elders, chiefs and councils | D8: 6 | Q8: =SUM(D8:P8) -> 6 | R8: =IF(Q8=Topics!M8,"ok","differs from Topics") -> ok
A9: T1-3-008 | B9: Tier 1-3 | C9: Our oldest ancestors, in East Africa | E9: 8 | Q9: =SUM(D9:P9) -> 8 | R9: =IF(Q9=Topics!M9,"ok","differs from Topics") -> ok
A10: T1-3-009 | B10: Tier 1-3 | C10: Stone tools, fire and shelter | E10: 7 | Q10: =SUM(D10:P10) -> 7 | R10: =IF(Q10=Topics!M10,"ok","differs from Topics") -> ok
A11: T1-3-010 | B11: Tier 1-3 | C11: Hunting, fishing and gathering | E11: 6 | Q11: =SUM(D11:P11) -> 6 | R11: =IF(Q11=Topics!M11,"ok","differs from Topics") -> ok
A12: T1-3-011 | B12: Tier 1-3 | C12: Rock art and beads | E12: 6 | Q12: =SUM(D12:P12) -> 6 | R12: =IF(Q12=Topics!M12,"ok","differs from Topics") -> ok
A13: T1-3-012 | B13: Tier 1-3 | C13: People reach every continent | E13: 6 | Q13: =SUM(D13:P13) -> 6 | R13: =IF(Q13=Topics!M13,"ok","differs from Topics") -> ok
A14: T1-3-013 | B14: Tier 1-3 | C14: The first farmers and their crops | F14: 9 | Q14: =SUM(D14:P14) -> 9 | R14: =IF(Q14=Topics!M14,"ok","differs from Topics") -> ok
A15: T1-3-014 | B15: Tier 1-3 | C15: Taming animals | F15: 6 | Q15: =SUM(D15:P15) -> 6 | R15: =IF(Q15=Topics!M15,"ok","differs from Topics") -> ok
A16: T1-3-015 | B16: Tier 1-3 | C16: Villages, towns and the first cities | F16: 6 | Q16: =SUM(D16:P16) -> 6 | R16: =IF(Q16=Topics!M16,"ok","differs from Topics") -> ok
A17: T1-3-016 | B17: Tier 1-3 | C17: Writing, paper and counting | F17: 10 | Q17: =SUM(D17:P17) -> 10 | R17: =IF(Q17=Topics!M17,"ok","differs from Topics") -> ok
A18: T1-3-017 | B18: Tier 1-3 | C18: Wheels, boats, roads and bridges | F18: 6 | Q18: =SUM(D18:P18) -> 6 | R18: =IF(Q18=Topics!M18,"ok","differs from Topics") -> ok
A19: T1-3-018 | B19: Tier 1-3 | C19: Markets and money | E19: 3 | F19: 5 | Q19: =SUM(D19:P19) -> 8 | R19: =IF(Q19=Topics!M19,"ok","differs from Topics") -> ok
A20: T1-3-019 | B20: Tier 1-3 | C20: Great buildings and their builders | F20: 6 | Q20: =SUM(D20:P20) -> 6 | R20: =IF(Q20=Topics!M20,"ok","differs from Topics") -> ok
A21: T1-3-020 | B21: Tier 1-3 | C21: Long ago in Africa | F21: 8 | Q21: =SUM(D21:P21) -> 8 | R21: =IF(Q21=Topics!M21,"ok","differs from Topics") -> ok
A22: T1-3-021 | B22: Tier 1-3 | C22: Long ago in Asia | F22: 8 | Q22: =SUM(D22:P22) -> 8 | R22: =IF(Q22=Topics!M22,"ok","differs from Topics") -> ok
A23: T1-3-022 | B23: Tier 1-3 | C23: Long ago in the Americas | F23: 6 | Q23: =SUM(D23:P23) -> 6 | R23: =IF(Q23=Topics!M23,"ok","differs from Topics") -> ok
A24: T1-3-023 | B24: Tier 1-3 | C24: Long ago around the Mediterranean | F24: 5 | Q24: =SUM(D24:P24) -> 5 | R24: =IF(Q24=Topics!M24,"ok","differs from Topics") -> ok
A25: T1-3-024 | B25: Tier 1-3 | C25: Holy places in history | D25: 2 | E25: 2 | F25: 2 | Q25: =SUM(D25:P25) -> 6 | R25: =IF(Q25=Topics!M25,"ok","differs from Topics") -> ok
A26: T1-3-025 | B26: Tier 1-3 | C26: Famous journeys | F26: 4 | Q26: =SUM(D26:P26) -> 4 | R26: =IF(Q26=Topics!M26,"ok","differs from Topics") -> ok
A27: T1-3-026 | B27: Tier 1-3 | C27: People who changed the world | F27: 8 | Q27: =SUM(D27:P27) -> 8 | R27: =IF(Q27=Topics!M27,"ok","differs from Topics") -> ok
A28: T1-3-027 | B28: Tier 1-3 | C28: Keeping well: water, nurses and vaccines | F28: 6 | Q28: =SUM(D28:P28) -> 6 | R28: =IF(Q28=Topics!M28,"ok","differs from Topics") -> ok
A29: T1-3-028 | B29: Tier 1-3 | C29: Caring for land and forests | E29: 3 | F29: 3 | Q29: =SUM(D29:P29) -> 6 | R29: =IF(Q29=Topics!M29,"ok","differs from Topics") -> ok
A30: T1-3-029 | B30: Tier 1-3 | C30: Heritage near us: Tanzania | E30: 2 | F30: 2 | Q30: =SUM(D30:P30) -> 4 | R30: =IF(Q30=Topics!M30,"ok","differs from Topics") -> ok
A31: T1-3-030 | B31: Tier 1-3 | C31: Village life then and now: an East African homestead and a Himalayan farm | D31: 3 | E31: 3 | Q31: =SUM(D31:P31) -> 6 | R31: =IF(Q31=Topics!M31,"ok","differs from Topics") -> ok
A32: T1-3-031 | B32: Tier 1-3 | C32: Heritage near us: Bhutan | E32: 2 | F32: 2 | Q32: =SUM(D32:P32) -> 4 | R32: =IF(Q32=Topics!M32,"ok","differs from Topics") -> ok
A33: T4-6-001 | B33: Tier 4-6 | C33: The long timeline | G33: 4 | Q33: =SUM(D33:P33) -> 4 | R33: =IF(Q33=Topics!M33,"ok","differs from Topics") -> ok
A34: T4-6-002 | B34: Tier 4-6 | C34: How we know: sources, dates and timelines | G34: 4 | H34: 4 | Q34: =SUM(D34:P34) -> 8 | R34: =IF(Q34=Topics!M34,"ok","differs from Topics") -> ok
A35: T4-6-003 | B35: Tier 4-6 | C35: Human origins in Africa | G35: 12 | Q35: =SUM(D35:P35) -> 12 | R35: =IF(Q35=Topics!M35,"ok","differs from Topics") -> ok
A36: T4-6-004 | B36: Tier 4-6 | C36: Origin stories and what the evidence shows | G36: 5 | Q36: =SUM(D36:P36) -> 5 | R36: =IF(Q36=Topics!M36,"ok","differs from Topics") -> ok
A37: T4-6-005 | B37: Tier 4-6 | C37: Ice Age people and the peopling of the world | G37: 9 | Q37: =SUM(D37:P37) -> 9 | R37: =IF(Q37=Topics!M37,"ok","differs from Topics") -> ok
A38: T4-6-006 | B38: Tier 4-6 | C38: The farming revolution | G38: 12 | Q38: =SUM(D38:P38) -> 12 | R38: =IF(Q38=Topics!M38,"ok","differs from Topics") -> ok
A39: T4-6-007 | B39: Tier 4-6 | C39: The green Sahara and Africa's first farmers | G39: 6 | Q39: =SUM(D39:P39) -> 6 | R39: =IF(Q39=Topics!M39,"ok","differs from Topics") -> ok
A40: T4-6-008 | B40: Tier 4-6 | C40: Metals, wheels and horses | G40: 8 | Q40: =SUM(D40:P40) -> 8 | R40: =IF(Q40=Topics!M40,"ok","differs from Topics") -> ok
...

Sheet Tiers
A1: Tier | B1: Levels | C1: What the tier covers | D1: What a card looks like | E1: Cards
A2: Tier 1-3 | B2: 1, 2, 3 | C2: Level 1 is the child's world then and now, with time, family, homes, travel, festivals and leaders. Level 2 covers human ancestors in East Africa, Stone Age life, and family life then and now in two places. Level 3 covers first farmers, towns and cities, writing, money, famous places, journeys and helpers from every continent. All new. | D2: Level 1 about 15 to 25 words in 3 to 6 sentences, no glossary, one-word options, written to be read aloud by a teacher or parent. Level 2 about 40 words in 3 to 6 sentences, at most one glossary word. Level 3 about 60 to 70 words in 5 to 9 sentences on the front, as on the sample card about paper, with up to three glossary words on the back. The picture shows the setting or one clue, never the answer, and no question asks what the picture shows. One concrete thing per card. Questions: which one, what was it for, which came first, then or now. Nothing frightening. | E2: =SUMIF(Topics!$B$2:$B$213,A2,Topics!$M$2:$M$213) -> 223
A3: Tier 4-6 | B3: 4, 5, 6 | C3: Levels 4-5: human origins to about 500 CE, Big Eras 1-4, with farming, river civilisations, early states in Africa, Asia and the Americas, traditional leadership, early belief and classical empires. Level 6: the 80 existing level-6 cards plus first-look cards on Africa, Asia, Latin America and the Middle East, so every pupil meets the whole timeline once. | D3: House format, about 80 to 110 words in 7 to 12 sentences of about seven words, glossary for words outside the 1,000 most common. Anonymised clue chain. Questions: identify, order two events, one simple cause or result. Centuries, not exact years. Belief marked as belief. | E3: =SUMIF(Topics!$B$2:$B$213,A3,Topics!$M$2:$M$213) -> 320
A4: Tier 7-9 | B4: 7, 8, 9 | C4: About 300 to 1900, Big Eras 5-7. Level 7: Islam and the medieval worlds of Africa, Asia, Europe, the Americas and the Pacific, and how we know about states with few written records. Level 8: 1450-1800, with voyages, the Columbian Exchange, slave trades, land empires, and limited and absolute monarchy. Level 9: 1750-1900, with revolutions, industry, abolition, migration and conquest, plus the 80 existing level-9 cards. | D4: About 100 to 130 words in 9 to 12 sentences, three to five glossary words, two or three linked clues across regions or from cause to effect. Questions on cause and consequence, comparison, change over time and how we know. Key dates allowed. Conquest and slavery told from more than one side, no gore. | E4: =SUMIF(Topics!$B$2:$B$213,A4,Topics!$M$2:$M$213) -> 405
A5: Tier 10-U | B5: 10, 11, 12, U | C5: Level 10: 1848-1945 on Cambridge IGCSE Option A, Option B key questions 1-3 and depth studies A-E. Level 11: the world since 1945, with IGCSE Option B key questions 4-6 for the Cold War and the other layers for decolonisation, rights, globalisation and the environment. Level 12: Cambridge AS Level depth and comparison across eras, with 160 existing cards. U: A Level Papers 3 and 4, AP World History: Modern and the NCHS grade 9-12 standards, for evidence, myths and interpretations, with 80 existing cards. | D5: About 110 to 140 words in 9 to 12 short sentences, with abstract terms such as mandate or interpretation in the glossary. Levels 10-11 ask for causes, results and significance; 12 compares and tracks change; U asks which evidence supports a claim or which view a historian holds. One defensible answer of four. Sensitive topics through facts and testimony, with no victim images. | E5: =SUMIF(Topics!$B$2:$B$213,A5,Topics!$M$2:$M$213) -> 571

Sheet Level outcomes
A1: Level | B1: Tier | C1: Outcome ID | D1: By the end of the level, students can | E1: Standard mapping | F1: Topic rows that teach it
A2: 1 | B2: Tier 1-3 | C2: H1.1 | D2: By the end of level 1, students can use time words such as before, after, long ago and today, and put two events in order. | E2: NCHS K-4 Historical Thinking Standard 1, Chronological Thinking; BNCC EF02HI06; Cambridge Primary Humanities 0065, Past strand | F2: T1-3-001
A3: 1 | B3: Tier 1-3 | C3: H1.2 | D3: By the end of level 1, students can tell an old object from a new one and say what each was for, such as an oil lamp and a light bulb. | E3: NCHS K-4 Topic 4, Standard 8A; England National Curriculum 2013, KS1, changes within living memory | F3: T1-3-003, T1-3-030
A4: 1 | B4: Tier 1-3 | C4: H1.3 | D4: By the end of level 1, students can describe how children lived long ago, such as how they learned, played and travelled, and say what has changed and what is still the same today. | E4: NCHS K-4 Topic 1, Standard 1; Tanzania HTM primary 2023, Std III; IB PYP Social studies scope and sequence 2008, age band 5-7, reference only | F4: T1-3-002, T1-3-003, T1-3-030
A5: 1 | B5: Tier 1-3 | C5: H1.4 | D5: By the end of level 1, students can name clues about the past, such as old objects, photographs, buildings and stories told by grandparents. | E5: Cambridge Primary Humanities 0065, Past strand, how we construct the past; NCHS K-4 Topic 4, Standard 7A | F5: T1-3-004
A6: 1 | B6: Tier 1-3 | C6: H1.5 | D6: By the end of level 1, students can recognise that people everywhere mark special days with stories, songs and festivals, and that some festivals come from religious belief. | E6: NCHS K-4 Topic 4, Standard 7A, folktales, holidays and ceremonies; Tanzania HTM primary 2023, Std III | F6: T1-3-005, T1-3-024
A7: 1 | B7: Tier 1-3 | C7: H1.6 | D7: By the end of level 1, students can compare how people travelled and sent messages long ago and today, such as camels, boats, drums, letters and phones. | E7: NCHS K-4 Topic 4, Standards 8B and 8C | F7: T1-3-006
A8: 1 | B8: Tier 1-3 | C8: H1.7 | D8: By the end of level 1, students can name who makes rules in a family, a school and a village, and say that leaders long ago were often elders, chiefs, kings or queens. | E8: WHFUA key theme Uses and Abuses of Power; Tanzania HTM primary 2023, Std III, leadership at family, clan and school level; Bhutan Social Studies 2025, Class IV, local government | F8: T1-3-007
A9: 2 | B9: Tier 1-3 | C9: H2.1 | D9: By the end of level 2, students can say that the first humans and their older ancestors lived in Africa, and that very old footprints and bones of these ancestors were found in Tanzania and Ethiopia. | E9: WHFUA Big Era 1, Landscape 1.2; NCHS World History Era 1, Standard 1; Kenya KICD Junior School Grade 8 | F9: T1-3-008
A10: 2 | B10: Tier 1-3 | C10: H2.2 | D10: By the end of level 2, students can describe how early people found food by hunting, fishing and gathering plants. | E10: NCHS K-4 Topic 4, Standard 8A; WHFUA Big Era 2, Landscape 2.1 | F10: T1-3-010
A11: 2 | B11: Tier 1-3 | C11: H2.3 | D11: By the end of level 2, students can name the first tools and skills of early people: stone tools, fire, clothes and shelters. | E11: NCHS K-4 Topic 4, Standard 8A; England National Curriculum 2013, KS2, Stone Age to Iron Age | F11: T1-3-009
A12: 2 | B12: Tier 1-3 | C12: H2.4 | D12: By the end of level 2, students can recognise that early people painted on rocks and made beads, and that these are clues about their lives. | E12: WHFUA Big Era 2, Landscape 2.1; NCHS K-4 Topic 4, Standard 7A | F12: T1-3-011
... A104: U | B104: Tier 10-U | C104: HU.8 | D104: By the end of university level, students can explain when, by whom and why the sources about a religious founder were written, and what historians can and cannot know from them. | E104: AP World History: Modern Skill 2, Sourcing and Situation; Cambridge 9489 AO3; Tanzania History A-level 2023, Form V | F104: T10-U-004

Sheet Standards
A1: Role | B1: Standard | C1: Code and version | D1: Levels | E1: Used for | F1: Link
A2: Primary: content spine | B2: World History for Us All, Big Eras 1-9 (UCLA Public History Initiative) | C2: Big Eras 1-9 | D2: 1-U | E2: Global, chronological spine for every level, including everything before 1774 that Cambridge does not examine. | F2: https://whfua.history.ucla.edu/bigeras.php
A3: Primary: outcome wording | B3: National Standards for History, Basic Edition (NCHS, UCLA) | C3: 1996; K-4 standards and World History Eras 1-9 for grades 5-12 | D3: 1-12 | E3: Outcome wording with grade bands: K-4 standards for levels 1-4 and world-history Eras 1-9 for grades 5-12; Historical Thinking Standards for skills. | F3: https://phi.history.ucla.edu/nchs/world-history-content-standards/
A4: Primary: exam standard | B4: Cambridge IGCSE History (same content: IGCSE 9-1 History 0977, O Level History 2147) | C4: 0470, syllabus 2027-2028 and 2029-2030 | D4: 10-11 | E4: Named exam standard for levels 10-11: content from 1848 to about 1989, Option A nineteenth century, Option B international relations since 1919, depth studies A-E. Assessment objectives AO1 and AO2. | F4: https://www.cambridgeinternational.org/programmes-and-qualifications/cambridge-igcse-history-0470/
A5: Primary: exam standard | B5: Cambridge International AS & A Level History | C5: 9489, syllabus 2027-2029, version 2 | D5: 12-U | E5: Named exam standard for level 12, with Papers 3 and 4 at U: content and key concepts from 1774 to 1994. | F5: https://www.cambridgeinternational.org/programmes-and-qualifications/cambridge-international-as-and-a-level-history-9489/
A6: Primary: university benchmark | B6: AP World History: Modern (College Board) | C6: Course and Exam Description, effective fall 2026 | D6: U | E6: University-equivalent survey of world history from about 1200 to the present; the College Board designs it as the equivalent of an introductory college course. | F6: https://apcentral.collegeboard.org/courses/ap-world-history
A7: Supporting | B7: Cambridge Primary Humanities, Past strand | C7: 0065, Stages 1-6 | D7: 1-6 | E7: Supporting wording for the history skills outcomes for levels 1-6: time and chronology, change, how we know about the past. Cambridge prescribes no history content at this stage. | F7: https://www.cambridgeinternational.org/programmes-and-qualifications/cambridge-primary/curriculum/humanities/
A8: Supporting | B8: Cambridge Lower Secondary Humanities, Past strand | C8: 0839, Stages 7-9 | D8: 7-9 | E8: Supporting wording for the history skills outcomes for levels 7-9. No prescribed content. | F8: https://www.cambridgeinternational.org/programmes-and-qualifications/cambridge-lower-secondary/curriculum/humanities/
A9: Reference | B9: IB Diploma Programme History | C9: Guide for first assessment 2028 | D9: 11-12 | E9: Cross-check of regional balance at upper secondary. Cited as a reference only; the cards are not endorsed by the IB. | F9: https://ibo.org/programmes/diploma-programme/curriculum/individuals-and-societies/history/
A10: Relevance check | B10: Bhutan History Curriculum Framework, Classes VII-XII | C10: Department of School Education, 2022 | D10: 7-12 | E10: World History strand and topic weights for Bhutanese pupils; Bhutan has aligned its curriculum with Cambridge since 2025. | F10: https://rec.gov.bt/download/56/curriculum-frameworks/5365/history-curriculum-framework-2022.pdf
A11: Relevance check | B11: Tanzania History syllabi, Form I-IV and Form V-VI | C11: Tanzania Institute of Education, 2023 | D11: 7-12 | E11: Africa-centred topics and competences for Tanzanian pupils. | F11: https://www.tie.go.tz/publications/syllabus-for-lower-secondary-academics
A12: Relevance check | B12: India NCERT, Kenya CBC, Brazil BNCC, England National Curriculum | C12: Current editions, checked October 2026 | D12: 1-12 | E12: Common core of world-history topics across national curricula in the regions the cards serve. | F12: https://www.gov.uk/government/publications/national-curriculum-in-england-history-programmes-of-study/national-curriculum-in-england-history-programmes-of-study
... A15: Not used | B15: ICCS (IEA) | C15: - | D15: - | E15: Assesses civic and citizenship knowledge at grade 8, not history. | F15: https://www.iea.nl/studies/iea/iccs

Sheet Existing cards
A1: Card ID | B1: Topic | C1: Card | D1: Level | E1: Tier | F1: Title | G1: Question | H1: Answer | I1: Map row | J1: Card set
A2: 001-1 | B2: Ancient Egypt: the pyramids | C2: 1 | D2: H 6 | E2: Tier 4-6 | F2: A land by one long river | G2: Which land is this? | H2: Egypt | I2: T4-6-009 | J2: ancient-egypt-pyramids
A3: 001-2 | B3: Ancient Egypt: the pyramids | C3: 2 | D3: H 9 | E3: Tier 7-9 | F3: Thousands of workers, no modern machines | G3: Which land is this? | H3: Egypt | I3: T7-9-066 | J3: ancient-egypt-pyramids
A4: 001-3 | B4: Ancient Egypt: the pyramids | C4: 3 | D4: H 12 | E4: Tier 10-U | F4: A mountain of stone | G4: Which land is this? | H4: Egypt | I4: T10-U-001 | J4: ancient-egypt-pyramids
A5: 001-4 | B5: Ancient Egypt: the pyramids | C5: 4 | D5: H 12 | E5: Tier 10-U | F5: The scribes and the flood | G5: Which land is this? | H5: Egypt | I5: T10-U-001 | J5: ancient-egypt-pyramids
A6: 001-5 | B6: Ancient Egypt: the pyramids | C6: 5 | D6: H U | E6: Tier 10-U | F6: The stone with three scripts | G6: Which land is this? | H6: Egypt | I6: T10-U-001 | J6: ancient-egypt-pyramids
A7: 002-1 | B7: Mesopotamia: the first cities and writing | C7: 1 | D7: H 6 | E7: Tier 4-6 | F7: The Land Between Two Rivers | G7: Which land is this? | H7: Mesopotamia | I7: T4-6-010 | J7: mesopotamia
A8: 002-2 | B8: Mesopotamia: the first cities and writing | C8: 2 | D8: H 9 | E8: Tier 7-9 | F8: Why People Invent Writing | G8: Which land is this? | H8: Mesopotamia | I8: T7-9-066 | J8: mesopotamia
A9: 002-3 | B9: Mesopotamia: the first cities and writing | C9: 3 | D9: H 12 | E9: Tier 10-U | F9: The City: A Big Invention | G9: Which land is this? | H9: Mesopotamia | I9: T10-U-001 | J9: mesopotamia
A10: 002-4 | B10: Mesopotamia: the first cities and writing | C10: 4 | D10: H 12 | E10: Tier 10-U | F10: The First Great Story | G10: Which land is this? | H10: Mesopotamia | I10: T10-U-001 | J10: mesopotamia
A11: 002-5 | B11: Mesopotamia: the first cities and writing | C11: 5 | D11: H U | E11: Tier 10-U | F11: Clay Outlasts Paper | G11: Which land is this? | H11: Mesopotamia | I11: T10-U-001 | J11: mesopotamia
A12: 003-1 | B12: Hammurabi and his law code | C12: 1 | D12: H 6 | E12: Tier 4-6 | F12: The King and the Tall Law Stone | G12: Who is King X? | H12: Hammurabi | I12: T4-6-010 | J12: hammurabi
A13: 003-2 | B13: Hammurabi and his law code | C13: 2 | D13: H 9 | E13: Tier 7-9 | F13: Laws for All to See | G13: Who is King X? | H13: Hammurabi | I13: T7-9-066 | J13: hammurabi
... A401: 080-5 | B401: The Ottoman Empire | C401: 5 | D401: H U | E401: Tier 10-U | F401: Decline, or something else? | G401: Which empire is Empire X? | H401: The Ottoman Empire | I401: T10-U-017 | J401: ottoman-empire
